[2024-02-15T23:53:50.630+0000] {processor.py:161} INFO - Started process (PID=95) to work on /opt/airflow/dags/twitter_dag.py
[2024-02-15T23:53:50.630+0000] {processor.py:830} INFO - Processing file /opt/airflow/dags/twitter_dag.py for tasks to queue
[2024-02-15T23:53:50.631+0000] {logging_mixin.py:188} INFO - [2024-02-15T23:53:50.631+0000] {dagbag.py:538} INFO - Filling up the DagBag from /opt/airflow/dags/twitter_dag.py
[2024-02-15T23:53:50.633+0000] {logging_mixin.py:188} INFO - [2024-02-15T23:53:50.632+0000] {dagbag.py:348} ERROR - Failed to import: /opt/airflow/dags/twitter_dag.py
Traceback (most recent call last):
  File "/home/airflow/.local/lib/python3.8/site-packages/airflow/models/dagbag.py", line 344, in parse
    loader.exec_module(new_module)
  File "<frozen importlib._bootstrap_external>", line 839, in exec_module
  File "<frozen importlib._bootstrap_external>", line 976, in get_code
  File "<frozen importlib._bootstrap_external>", line 906, in source_to_code
  File "<frozen importlib._bootstrap>", line 219, in _call_with_frames_removed
  File "/opt/airflow/dags/twitter_dag.py", line 24
    EmptyOperator(task_id="task", dag=my_dag)
    ^
IndentationError: unexpected indent
[2024-02-15T23:53:50.633+0000] {processor.py:842} WARNING - No viable dags retrieved from /opt/airflow/dags/twitter_dag.py
[2024-02-15T23:53:50.648+0000] {processor.py:183} INFO - Processing /opt/airflow/dags/twitter_dag.py took 0.020 seconds
[2024-02-15T23:54:20.799+0000] {processor.py:161} INFO - Started process (PID=102) to work on /opt/airflow/dags/twitter_dag.py
[2024-02-15T23:54:20.800+0000] {processor.py:830} INFO - Processing file /opt/airflow/dags/twitter_dag.py for tasks to queue
[2024-02-15T23:54:20.801+0000] {logging_mixin.py:188} INFO - [2024-02-15T23:54:20.801+0000] {dagbag.py:538} INFO - Filling up the DagBag from /opt/airflow/dags/twitter_dag.py
[2024-02-15T23:54:20.803+0000] {logging_mixin.py:188} INFO - [2024-02-15T23:54:20.803+0000] {dagbag.py:348} ERROR - Failed to import: /opt/airflow/dags/twitter_dag.py
Traceback (most recent call last):
  File "/home/airflow/.local/lib/python3.8/site-packages/airflow/models/dagbag.py", line 344, in parse
    loader.exec_module(new_module)
  File "<frozen importlib._bootstrap_external>", line 839, in exec_module
  File "<frozen importlib._bootstrap_external>", line 976, in get_code
  File "<frozen importlib._bootstrap_external>", line 906, in source_to_code
  File "<frozen importlib._bootstrap>", line 219, in _call_with_frames_removed
  File "/opt/airflow/dags/twitter_dag.py", line 24
    EmptyOperator(task_id="task", dag=my_dag)
    ^
IndentationError: unexpected indent
[2024-02-15T23:54:20.804+0000] {processor.py:842} WARNING - No viable dags retrieved from /opt/airflow/dags/twitter_dag.py
[2024-02-15T23:54:20.818+0000] {processor.py:183} INFO - Processing /opt/airflow/dags/twitter_dag.py took 0.021 seconds
[2024-02-15T23:54:50.957+0000] {processor.py:161} INFO - Started process (PID=109) to work on /opt/airflow/dags/twitter_dag.py
[2024-02-15T23:54:50.958+0000] {processor.py:830} INFO - Processing file /opt/airflow/dags/twitter_dag.py for tasks to queue
[2024-02-15T23:54:50.959+0000] {logging_mixin.py:188} INFO - [2024-02-15T23:54:50.959+0000] {dagbag.py:538} INFO - Filling up the DagBag from /opt/airflow/dags/twitter_dag.py
[2024-02-15T23:54:50.961+0000] {logging_mixin.py:188} INFO - [2024-02-15T23:54:50.960+0000] {dagbag.py:348} ERROR - Failed to import: /opt/airflow/dags/twitter_dag.py
Traceback (most recent call last):
  File "/home/airflow/.local/lib/python3.8/site-packages/airflow/models/dagbag.py", line 344, in parse
    loader.exec_module(new_module)
  File "<frozen importlib._bootstrap_external>", line 839, in exec_module
  File "<frozen importlib._bootstrap_external>", line 976, in get_code
  File "<frozen importlib._bootstrap_external>", line 906, in source_to_code
  File "<frozen importlib._bootstrap>", line 219, in _call_with_frames_removed
  File "/opt/airflow/dags/twitter_dag.py", line 24
    EmptyOperator(task_id="task", dag=my_dag)
    ^
IndentationError: unexpected indent
[2024-02-15T23:54:50.961+0000] {processor.py:842} WARNING - No viable dags retrieved from /opt/airflow/dags/twitter_dag.py
[2024-02-15T23:54:50.974+0000] {processor.py:183} INFO - Processing /opt/airflow/dags/twitter_dag.py took 0.020 seconds
[2024-02-15T23:55:12.092+0000] {processor.py:161} INFO - Started process (PID=116) to work on /opt/airflow/dags/twitter_dag.py
[2024-02-15T23:55:12.093+0000] {processor.py:830} INFO - Processing file /opt/airflow/dags/twitter_dag.py for tasks to queue
[2024-02-15T23:55:12.095+0000] {logging_mixin.py:188} INFO - [2024-02-15T23:55:12.094+0000] {dagbag.py:538} INFO - Filling up the DagBag from /opt/airflow/dags/twitter_dag.py
[2024-02-15T23:55:12.106+0000] {logging_mixin.py:188} INFO - [2024-02-15T23:55:12.106+0000] {dagbag.py:348} ERROR - Failed to import: /opt/airflow/dags/twitter_dag.py
Traceback (most recent call last):
  File "/home/airflow/.local/lib/python3.8/site-packages/airflow/models/dagbag.py", line 344, in parse
    loader.exec_module(new_module)
  File "<frozen importlib._bootstrap_external>", line 843, in exec_module
  File "<frozen importlib._bootstrap>", line 219, in _call_with_frames_removed
  File "/opt/airflow/dags/twitter_dag.py", line 20, in <module>
    start_date=datetime.datetime(2021, 1, 1),
AttributeError: type object 'datetime.datetime' has no attribute 'datetime'
[2024-02-15T23:55:12.107+0000] {processor.py:842} WARNING - No viable dags retrieved from /opt/airflow/dags/twitter_dag.py
[2024-02-15T23:55:12.120+0000] {processor.py:183} INFO - Processing /opt/airflow/dags/twitter_dag.py took 0.030 seconds
[2024-02-15T23:55:21.144+0000] {processor.py:161} INFO - Started process (PID=117) to work on /opt/airflow/dags/twitter_dag.py
[2024-02-15T23:55:21.145+0000] {processor.py:830} INFO - Processing file /opt/airflow/dags/twitter_dag.py for tasks to queue
[2024-02-15T23:55:21.146+0000] {logging_mixin.py:188} INFO - [2024-02-15T23:55:21.146+0000] {dagbag.py:538} INFO - Filling up the DagBag from /opt/airflow/dags/twitter_dag.py
[2024-02-15T23:55:21.151+0000] {logging_mixin.py:188} INFO - [2024-02-15T23:55:21.151+0000] {dagbag.py:348} ERROR - Failed to import: /opt/airflow/dags/twitter_dag.py
Traceback (most recent call last):
  File "/home/airflow/.local/lib/python3.8/site-packages/airflow/models/dagbag.py", line 344, in parse
    loader.exec_module(new_module)
  File "<frozen importlib._bootstrap_external>", line 843, in exec_module
  File "<frozen importlib._bootstrap>", line 219, in _call_with_frames_removed
  File "/opt/airflow/dags/twitter_dag.py", line 20, in <module>
    start_date=datetime.datetime(2021, 1, 1),
AttributeError: type object 'datetime.datetime' has no attribute 'datetime'
[2024-02-15T23:55:21.152+0000] {processor.py:842} WARNING - No viable dags retrieved from /opt/airflow/dags/twitter_dag.py
[2024-02-15T23:55:21.164+0000] {processor.py:183} INFO - Processing /opt/airflow/dags/twitter_dag.py took 0.022 seconds
[2024-02-15T23:55:22.170+0000] {processor.py:161} INFO - Started process (PID=118) to work on /opt/airflow/dags/twitter_dag.py
[2024-02-15T23:55:22.170+0000] {processor.py:830} INFO - Processing file /opt/airflow/dags/twitter_dag.py for tasks to queue
[2024-02-15T23:55:22.172+0000] {logging_mixin.py:188} INFO - [2024-02-15T23:55:22.171+0000] {dagbag.py:538} INFO - Filling up the DagBag from /opt/airflow/dags/twitter_dag.py
[2024-02-15T23:55:22.177+0000] {logging_mixin.py:188} INFO - [2024-02-15T23:55:22.177+0000] {dagbag.py:348} ERROR - Failed to import: /opt/airflow/dags/twitter_dag.py
Traceback (most recent call last):
  File "/home/airflow/.local/lib/python3.8/site-packages/airflow/models/dagbag.py", line 344, in parse
    loader.exec_module(new_module)
  File "<frozen importlib._bootstrap_external>", line 843, in exec_module
  File "<frozen importlib._bootstrap>", line 219, in _call_with_frames_removed
  File "/opt/airflow/dags/twitter_dag.py", line 20, in <module>
    start_date=datetime.datetime(2021, 1, 1),
AttributeError: type object 'datetime.datetime' has no attribute 'datetime'
[2024-02-15T23:55:22.177+0000] {processor.py:842} WARNING - No viable dags retrieved from /opt/airflow/dags/twitter_dag.py
[2024-02-15T23:55:22.191+0000] {processor.py:183} INFO - Processing /opt/airflow/dags/twitter_dag.py took 0.023 seconds
[2024-02-15T23:55:52.332+0000] {processor.py:161} INFO - Started process (PID=125) to work on /opt/airflow/dags/twitter_dag.py
[2024-02-15T23:55:52.332+0000] {processor.py:830} INFO - Processing file /opt/airflow/dags/twitter_dag.py for tasks to queue
[2024-02-15T23:55:52.333+0000] {logging_mixin.py:188} INFO - [2024-02-15T23:55:52.333+0000] {dagbag.py:538} INFO - Filling up the DagBag from /opt/airflow/dags/twitter_dag.py
[2024-02-15T23:55:52.341+0000] {logging_mixin.py:188} INFO - [2024-02-15T23:55:52.340+0000] {dagbag.py:348} ERROR - Failed to import: /opt/airflow/dags/twitter_dag.py
Traceback (most recent call last):
  File "/home/airflow/.local/lib/python3.8/site-packages/airflow/models/dagbag.py", line 344, in parse
    loader.exec_module(new_module)
  File "<frozen importlib._bootstrap_external>", line 843, in exec_module
  File "<frozen importlib._bootstrap>", line 219, in _call_with_frames_removed
  File "/opt/airflow/dags/twitter_dag.py", line 20, in <module>
    start_date=datetime.datetime(2021, 1, 1),
AttributeError: type object 'datetime.datetime' has no attribute 'datetime'
[2024-02-15T23:55:52.342+0000] {processor.py:842} WARNING - No viable dags retrieved from /opt/airflow/dags/twitter_dag.py
[2024-02-15T23:55:52.360+0000] {processor.py:183} INFO - Processing /opt/airflow/dags/twitter_dag.py took 0.030 seconds
[2024-02-15T23:56:09.437+0000] {processor.py:161} INFO - Started process (PID=132) to work on /opt/airflow/dags/twitter_dag.py
[2024-02-15T23:56:09.438+0000] {processor.py:830} INFO - Processing file /opt/airflow/dags/twitter_dag.py for tasks to queue
[2024-02-15T23:56:09.440+0000] {logging_mixin.py:188} INFO - [2024-02-15T23:56:09.440+0000] {dagbag.py:538} INFO - Filling up the DagBag from /opt/airflow/dags/twitter_dag.py
[2024-02-15T23:56:09.447+0000] {logging_mixin.py:188} INFO - [2024-02-15T23:56:09.447+0000] {dagbag.py:348} ERROR - Failed to import: /opt/airflow/dags/twitter_dag.py
Traceback (most recent call last):
  File "/home/airflow/.local/lib/python3.8/site-packages/airflow/models/dagbag.py", line 344, in parse
    loader.exec_module(new_module)
  File "<frozen importlib._bootstrap_external>", line 843, in exec_module
  File "<frozen importlib._bootstrap>", line 219, in _call_with_frames_removed
  File "/opt/airflow/dags/twitter_dag.py", line 20, in <module>
    start_date=datetime.datetime(2021, 1, 1),
AttributeError: type object 'datetime.datetime' has no attribute 'datetime'
[2024-02-15T23:56:09.447+0000] {processor.py:842} WARNING - No viable dags retrieved from /opt/airflow/dags/twitter_dag.py
[2024-02-15T23:56:09.459+0000] {processor.py:183} INFO - Processing /opt/airflow/dags/twitter_dag.py took 0.027 seconds
[2024-02-15T23:56:39.609+0000] {processor.py:161} INFO - Started process (PID=139) to work on /opt/airflow/dags/twitter_dag.py
[2024-02-15T23:56:39.610+0000] {processor.py:830} INFO - Processing file /opt/airflow/dags/twitter_dag.py for tasks to queue
[2024-02-15T23:56:39.612+0000] {logging_mixin.py:188} INFO - [2024-02-15T23:56:39.612+0000] {dagbag.py:538} INFO - Filling up the DagBag from /opt/airflow/dags/twitter_dag.py
[2024-02-15T23:56:39.618+0000] {logging_mixin.py:188} INFO - [2024-02-15T23:56:39.617+0000] {dagbag.py:348} ERROR - Failed to import: /opt/airflow/dags/twitter_dag.py
Traceback (most recent call last):
  File "/home/airflow/.local/lib/python3.8/site-packages/airflow/models/dagbag.py", line 344, in parse
    loader.exec_module(new_module)
  File "<frozen importlib._bootstrap_external>", line 843, in exec_module
  File "<frozen importlib._bootstrap>", line 219, in _call_with_frames_removed
  File "/opt/airflow/dags/twitter_dag.py", line 20, in <module>
    start_date=datetime.datetime(2021, 1, 1),
AttributeError: type object 'datetime.datetime' has no attribute 'datetime'
[2024-02-15T23:56:39.619+0000] {processor.py:842} WARNING - No viable dags retrieved from /opt/airflow/dags/twitter_dag.py
[2024-02-15T23:56:39.631+0000] {processor.py:183} INFO - Processing /opt/airflow/dags/twitter_dag.py took 0.024 seconds
[2024-02-15T23:56:48.677+0000] {processor.py:161} INFO - Started process (PID=140) to work on /opt/airflow/dags/twitter_dag.py
[2024-02-15T23:56:48.679+0000] {processor.py:830} INFO - Processing file /opt/airflow/dags/twitter_dag.py for tasks to queue
[2024-02-15T23:56:48.681+0000] {logging_mixin.py:188} INFO - [2024-02-15T23:56:48.681+0000] {dagbag.py:538} INFO - Filling up the DagBag from /opt/airflow/dags/twitter_dag.py
[2024-02-15T23:56:48.690+0000] {logging_mixin.py:188} INFO - [2024-02-15T23:56:48.689+0000] {dagbag.py:348} ERROR - Failed to import: /opt/airflow/dags/twitter_dag.py
Traceback (most recent call last):
  File "/home/airflow/.local/lib/python3.8/site-packages/airflow/models/dagbag.py", line 344, in parse
    loader.exec_module(new_module)
  File "<frozen importlib._bootstrap_external>", line 843, in exec_module
  File "<frozen importlib._bootstrap>", line 219, in _call_with_frames_removed
  File "/opt/airflow/dags/twitter_dag.py", line 20, in <module>
    start_date=datetime.datetime(2021, 1, 1),
AttributeError: type object 'datetime.datetime' has no attribute 'datetime'
[2024-02-15T23:56:48.690+0000] {processor.py:842} WARNING - No viable dags retrieved from /opt/airflow/dags/twitter_dag.py
[2024-02-15T23:56:48.705+0000] {processor.py:183} INFO - Processing /opt/airflow/dags/twitter_dag.py took 0.033 seconds
[2024-02-15T23:57:18.851+0000] {processor.py:161} INFO - Started process (PID=146) to work on /opt/airflow/dags/twitter_dag.py
[2024-02-15T23:57:18.852+0000] {processor.py:830} INFO - Processing file /opt/airflow/dags/twitter_dag.py for tasks to queue
[2024-02-15T23:57:18.853+0000] {logging_mixin.py:188} INFO - [2024-02-15T23:57:18.853+0000] {dagbag.py:538} INFO - Filling up the DagBag from /opt/airflow/dags/twitter_dag.py
[2024-02-15T23:57:18.858+0000] {logging_mixin.py:188} INFO - [2024-02-15T23:57:18.858+0000] {dagbag.py:348} ERROR - Failed to import: /opt/airflow/dags/twitter_dag.py
Traceback (most recent call last):
  File "/home/airflow/.local/lib/python3.8/site-packages/airflow/models/dagbag.py", line 344, in parse
    loader.exec_module(new_module)
  File "<frozen importlib._bootstrap_external>", line 843, in exec_module
  File "<frozen importlib._bootstrap>", line 219, in _call_with_frames_removed
  File "/opt/airflow/dags/twitter_dag.py", line 20, in <module>
    start_date=datetime.datetime(2021, 1, 1),
AttributeError: type object 'datetime.datetime' has no attribute 'datetime'
[2024-02-15T23:57:18.858+0000] {processor.py:842} WARNING - No viable dags retrieved from /opt/airflow/dags/twitter_dag.py
[2024-02-15T23:57:18.872+0000] {processor.py:183} INFO - Processing /opt/airflow/dags/twitter_dag.py took 0.023 seconds
[2024-02-15T23:57:26.901+0000] {processor.py:161} INFO - Started process (PID=147) to work on /opt/airflow/dags/twitter_dag.py
[2024-02-15T23:57:26.902+0000] {processor.py:830} INFO - Processing file /opt/airflow/dags/twitter_dag.py for tasks to queue
[2024-02-15T23:57:26.903+0000] {logging_mixin.py:188} INFO - [2024-02-15T23:57:26.903+0000] {dagbag.py:538} INFO - Filling up the DagBag from /opt/airflow/dags/twitter_dag.py
[2024-02-15T23:57:26.907+0000] {logging_mixin.py:188} INFO - [2024-02-15T23:57:26.907+0000] {dagbag.py:348} ERROR - Failed to import: /opt/airflow/dags/twitter_dag.py
Traceback (most recent call last):
  File "/home/airflow/.local/lib/python3.8/site-packages/airflow/models/dagbag.py", line 344, in parse
    loader.exec_module(new_module)
  File "<frozen importlib._bootstrap_external>", line 843, in exec_module
  File "<frozen importlib._bootstrap>", line 219, in _call_with_frames_removed
  File "/opt/airflow/dags/twitter_dag.py", line 20, in <module>
    start_date=datetime.datetime(2021, 1, 1),
AttributeError: type object 'datetime.datetime' has no attribute 'datetime'
[2024-02-15T23:57:26.908+0000] {processor.py:842} WARNING - No viable dags retrieved from /opt/airflow/dags/twitter_dag.py
[2024-02-15T23:57:26.921+0000] {processor.py:183} INFO - Processing /opt/airflow/dags/twitter_dag.py took 0.022 seconds
[2024-02-15T23:57:35.966+0000] {processor.py:161} INFO - Started process (PID=154) to work on /opt/airflow/dags/twitter_dag.py
[2024-02-15T23:57:35.967+0000] {processor.py:830} INFO - Processing file /opt/airflow/dags/twitter_dag.py for tasks to queue
[2024-02-15T23:57:35.968+0000] {logging_mixin.py:188} INFO - [2024-02-15T23:57:35.968+0000] {dagbag.py:538} INFO - Filling up the DagBag from /opt/airflow/dags/twitter_dag.py
[2024-02-15T23:57:35.973+0000] {logging_mixin.py:188} INFO - [2024-02-15T23:57:35.972+0000] {dagbag.py:348} ERROR - Failed to import: /opt/airflow/dags/twitter_dag.py
Traceback (most recent call last):
  File "/home/airflow/.local/lib/python3.8/site-packages/airflow/models/dagbag.py", line 344, in parse
    loader.exec_module(new_module)
  File "<frozen importlib._bootstrap_external>", line 843, in exec_module
  File "<frozen importlib._bootstrap>", line 219, in _call_with_frames_removed
  File "/opt/airflow/dags/twitter_dag.py", line 20, in <module>
    start_date=datetime.datetime(2021, 1, 1),
AttributeError: type object 'datetime.datetime' has no attribute 'datetime'
[2024-02-15T23:57:35.973+0000] {processor.py:842} WARNING - No viable dags retrieved from /opt/airflow/dags/twitter_dag.py
[2024-02-15T23:57:35.986+0000] {processor.py:183} INFO - Processing /opt/airflow/dags/twitter_dag.py took 0.021 seconds
[2024-02-15T23:58:06.128+0000] {processor.py:161} INFO - Started process (PID=161) to work on /opt/airflow/dags/twitter_dag.py
[2024-02-15T23:58:06.129+0000] {processor.py:830} INFO - Processing file /opt/airflow/dags/twitter_dag.py for tasks to queue
[2024-02-15T23:58:06.131+0000] {logging_mixin.py:188} INFO - [2024-02-15T23:58:06.131+0000] {dagbag.py:538} INFO - Filling up the DagBag from /opt/airflow/dags/twitter_dag.py
[2024-02-15T23:58:06.137+0000] {logging_mixin.py:188} INFO - [2024-02-15T23:58:06.137+0000] {dagbag.py:348} ERROR - Failed to import: /opt/airflow/dags/twitter_dag.py
Traceback (most recent call last):
  File "/home/airflow/.local/lib/python3.8/site-packages/airflow/models/dagbag.py", line 344, in parse
    loader.exec_module(new_module)
  File "<frozen importlib._bootstrap_external>", line 843, in exec_module
  File "<frozen importlib._bootstrap>", line 219, in _call_with_frames_removed
  File "/opt/airflow/dags/twitter_dag.py", line 20, in <module>
    start_date=datetime.datetime(2021, 1, 1),
AttributeError: type object 'datetime.datetime' has no attribute 'datetime'
[2024-02-15T23:58:06.138+0000] {processor.py:842} WARNING - No viable dags retrieved from /opt/airflow/dags/twitter_dag.py
[2024-02-15T23:58:06.150+0000] {processor.py:183} INFO - Processing /opt/airflow/dags/twitter_dag.py took 0.025 seconds
[2024-02-15T23:58:36.301+0000] {processor.py:161} INFO - Started process (PID=168) to work on /opt/airflow/dags/twitter_dag.py
[2024-02-15T23:58:36.301+0000] {processor.py:830} INFO - Processing file /opt/airflow/dags/twitter_dag.py for tasks to queue
[2024-02-15T23:58:36.304+0000] {logging_mixin.py:188} INFO - [2024-02-15T23:58:36.304+0000] {dagbag.py:538} INFO - Filling up the DagBag from /opt/airflow/dags/twitter_dag.py
[2024-02-15T23:58:36.312+0000] {logging_mixin.py:188} INFO - [2024-02-15T23:58:36.311+0000] {dagbag.py:348} ERROR - Failed to import: /opt/airflow/dags/twitter_dag.py
Traceback (most recent call last):
  File "/home/airflow/.local/lib/python3.8/site-packages/airflow/models/dagbag.py", line 344, in parse
    loader.exec_module(new_module)
  File "<frozen importlib._bootstrap_external>", line 843, in exec_module
  File "<frozen importlib._bootstrap>", line 219, in _call_with_frames_removed
  File "/opt/airflow/dags/twitter_dag.py", line 20, in <module>
    start_date=datetime.datetime(2021, 1, 1),
AttributeError: type object 'datetime.datetime' has no attribute 'datetime'
[2024-02-15T23:58:36.312+0000] {processor.py:842} WARNING - No viable dags retrieved from /opt/airflow/dags/twitter_dag.py
[2024-02-15T23:58:36.325+0000] {processor.py:183} INFO - Processing /opt/airflow/dags/twitter_dag.py took 0.027 seconds
[2024-02-15T23:59:06.505+0000] {processor.py:161} INFO - Started process (PID=175) to work on /opt/airflow/dags/twitter_dag.py
[2024-02-15T23:59:06.505+0000] {processor.py:830} INFO - Processing file /opt/airflow/dags/twitter_dag.py for tasks to queue
[2024-02-15T23:59:06.506+0000] {logging_mixin.py:188} INFO - [2024-02-15T23:59:06.506+0000] {dagbag.py:538} INFO - Filling up the DagBag from /opt/airflow/dags/twitter_dag.py
[2024-02-15T23:59:06.510+0000] {logging_mixin.py:188} INFO - [2024-02-15T23:59:06.510+0000] {dagbag.py:348} ERROR - Failed to import: /opt/airflow/dags/twitter_dag.py
Traceback (most recent call last):
  File "/home/airflow/.local/lib/python3.8/site-packages/airflow/models/dagbag.py", line 344, in parse
    loader.exec_module(new_module)
  File "<frozen importlib._bootstrap_external>", line 843, in exec_module
  File "<frozen importlib._bootstrap>", line 219, in _call_with_frames_removed
  File "/opt/airflow/dags/twitter_dag.py", line 20, in <module>
    start_date=datetime.datetime(2021, 1, 1),
AttributeError: type object 'datetime.datetime' has no attribute 'datetime'
[2024-02-15T23:59:06.511+0000] {processor.py:842} WARNING - No viable dags retrieved from /opt/airflow/dags/twitter_dag.py
[2024-02-15T23:59:06.524+0000] {processor.py:183} INFO - Processing /opt/airflow/dags/twitter_dag.py took 0.021 seconds
[2024-02-15T23:59:36.662+0000] {processor.py:161} INFO - Started process (PID=182) to work on /opt/airflow/dags/twitter_dag.py
[2024-02-15T23:59:36.662+0000] {processor.py:830} INFO - Processing file /opt/airflow/dags/twitter_dag.py for tasks to queue
[2024-02-15T23:59:36.664+0000] {logging_mixin.py:188} INFO - [2024-02-15T23:59:36.663+0000] {dagbag.py:538} INFO - Filling up the DagBag from /opt/airflow/dags/twitter_dag.py
[2024-02-15T23:59:36.668+0000] {logging_mixin.py:188} INFO - [2024-02-15T23:59:36.668+0000] {dagbag.py:348} ERROR - Failed to import: /opt/airflow/dags/twitter_dag.py
Traceback (most recent call last):
  File "/home/airflow/.local/lib/python3.8/site-packages/airflow/models/dagbag.py", line 344, in parse
    loader.exec_module(new_module)
  File "<frozen importlib._bootstrap_external>", line 843, in exec_module
  File "<frozen importlib._bootstrap>", line 219, in _call_with_frames_removed
  File "/opt/airflow/dags/twitter_dag.py", line 20, in <module>
    start_date=datetime.datetime(2021, 1, 1),
AttributeError: type object 'datetime.datetime' has no attribute 'datetime'
[2024-02-15T23:59:36.668+0000] {processor.py:842} WARNING - No viable dags retrieved from /opt/airflow/dags/twitter_dag.py
[2024-02-15T23:59:36.681+0000] {processor.py:183} INFO - Processing /opt/airflow/dags/twitter_dag.py took 0.021 seconds
[2024-02-15T23:59:56.793+0000] {processor.py:161} INFO - Started process (PID=183) to work on /opt/airflow/dags/twitter_dag.py
[2024-02-15T23:59:56.793+0000] {processor.py:830} INFO - Processing file /opt/airflow/dags/twitter_dag.py for tasks to queue
[2024-02-15T23:59:56.795+0000] {logging_mixin.py:188} INFO - [2024-02-15T23:59:56.794+0000] {dagbag.py:538} INFO - Filling up the DagBag from /opt/airflow/dags/twitter_dag.py
[2024-02-15T23:59:56.802+0000] {logging_mixin.py:188} INFO - [2024-02-15T23:59:56.802+0000] {dagbag.py:348} ERROR - Failed to import: /opt/airflow/dags/twitter_dag.py
Traceback (most recent call last):
  File "/home/airflow/.local/lib/python3.8/site-packages/airflow/models/dagbag.py", line 344, in parse
    loader.exec_module(new_module)
  File "<frozen importlib._bootstrap_external>", line 843, in exec_module
  File "<frozen importlib._bootstrap>", line 219, in _call_with_frames_removed
  File "/opt/airflow/dags/twitter_dag.py", line 20, in <module>
    start_date=datetime.datetime(2021, 1, 1),
AttributeError: type object 'datetime.datetime' has no attribute 'datetime'
[2024-02-15T23:59:56.803+0000] {processor.py:842} WARNING - No viable dags retrieved from /opt/airflow/dags/twitter_dag.py
[2024-02-15T23:59:56.816+0000] {processor.py:183} INFO - Processing /opt/airflow/dags/twitter_dag.py took 0.027 seconds
